Traceback (most recent call last):
  File "/home/runner/.cache/pypoetry/virtualenvs/draco-2B3Fy6YM-py3.9/lib/python3.9/site-packages/jupyter_cache/executors/utils.py", line 51, in single_nb_execution
    executenb(
  File "/home/runner/.cache/pypoetry/virtualenvs/draco-2B3Fy6YM-py3.9/lib/python3.9/site-packages/nbclient/client.py", line 1204, in execute
    return NotebookClient(nb=nb, resources=resources, km=km, **kwargs).execute()
  File "/home/runner/.cache/pypoetry/virtualenvs/draco-2B3Fy6YM-py3.9/lib/python3.9/site-packages/nbclient/util.py", line 84, in wrapped
    return just_run(coro(*args, **kwargs))
  File "/home/runner/.cache/pypoetry/virtualenvs/draco-2B3Fy6YM-py3.9/lib/python3.9/site-packages/nbclient/util.py", line 62, in just_run
    return loop.run_until_complete(coro)
  File "/opt/hostedtoolcache/Python/3.9.10/x64/lib/python3.9/asyncio/base_events.py", line 642, in run_until_complete
    return future.result()
  File "/home/runner/.cache/pypoetry/virtualenvs/draco-2B3Fy6YM-py3.9/lib/python3.9/site-packages/nbclient/client.py", line 663, in async_execute
    await self.async_execute_cell(
  File "/home/runner/.cache/pypoetry/virtualenvs/draco-2B3Fy6YM-py3.9/lib/python3.9/site-packages/nbclient/client.py", line 965, in async_execute_cell
    await self._check_raise_for_error(cell, cell_index, exec_reply)
  File "/home/runner/.cache/pypoetry/virtualenvs/draco-2B3Fy6YM-py3.9/lib/python3.9/site-packages/nbclient/client.py", line 862, in _check_raise_for_error
    raise CellExecutionError.from_cell_and_msg(cell, exec_reply_content)
nbclient.exceptions.CellExecutionError: An error occurred while executing the following cell:
------------------
show(
    data(["temperature"]),
    {
        "mark": [
            {
                "type": "bar",
                "encoding": [
                    {"channel": "x", "field": "temperature", "binning": 10},
                    {"channel": "y", "aggregate": "count"},
                ],
            }
        ],
        "scale": [
            {
                "channel": "x",
                "type": "linear",
            },
            {"channel": "y", "type": "linear"},
        ],
    },
)
------------------

[0;31m---------------------------------------------------------------------------[0m
[0;31mAssertionError[0m                            Traceback (most recent call last)
[0;32m/tmp/ipykernel_2859/2832237263.py[0m in [0;36m<module>[0;34m[0m
[0;32m----> 1[0;31m show(
[0m[1;32m      2[0m     [0mdata[0m[0;34m([0m[0;34m[[0m[0;34m"temperature"[0m[0;34m][0m[0;34m)[0m[0;34m,[0m[0;34m[0m[0;34m[0m[0m
[1;32m      3[0m     {
[1;32m      4[0m         "mark": [
[1;32m      5[0m             {

[0;32m/tmp/ipykernel_2859/1848947746.py[0m in [0;36mshow[0;34m(*args)[0m
[1;32m      8[0m         [0mprint[0m[0;34m([0m[0;34m"\n"[0m[0;34m.[0m[0mjoin[0m[0;34m([0m[0mprog[0m[0;34m)[0m[0;34m)[0m[0;34m[0m[0;34m[0m[0m
[1;32m      9[0m         [0mprint[0m[0;34m([0m[0mget_violations[0m[0;34m([0m[0mprog[0m[0;34m)[0m[0;34m)[0m[0;34m[0m[0;34m[0m[0m
[0;32m---> 10[0;31m         [0;32massert[0m [0;32mFalse[0m[0;34m,[0m [0;34m"Invalid spec"[0m[0;34m[0m[0;34m[0m[0m
[0m[1;32m     11[0m     [0;32mreturn[0m [0mprog[0m[0;34m[0m[0;34m[0m[0m

[0;31mAssertionError[0m: Invalid spec
AssertionError: Invalid spec

