Traceback (most recent call last):
  File "/home/runner/.virtualenvs/draco-2B3Fy6YM-py3.9/lib/python3.9/site-packages/jupyter_cache/executors/utils.py", line 51, in single_nb_execution
    executenb(
  File "/home/runner/.virtualenvs/draco-2B3Fy6YM-py3.9/lib/python3.9/site-packages/nbclient/client.py", line 1204, in execute
    return NotebookClient(nb=nb, resources=resources, km=km, **kwargs).execute()
  File "/home/runner/.virtualenvs/draco-2B3Fy6YM-py3.9/lib/python3.9/site-packages/nbclient/util.py", line 84, in wrapped
    return just_run(coro(*args, **kwargs))
  File "/home/runner/.virtualenvs/draco-2B3Fy6YM-py3.9/lib/python3.9/site-packages/nbclient/util.py", line 62, in just_run
    return loop.run_until_complete(coro)
  File "/opt/hostedtoolcache/Python/3.9.13/x64/lib/python3.9/asyncio/base_events.py", line 647, in run_until_complete
    return future.result()
  File "/home/runner/.virtualenvs/draco-2B3Fy6YM-py3.9/lib/python3.9/site-packages/nbclient/client.py", line 663, in async_execute
    await self.async_execute_cell(
  File "/home/runner/.virtualenvs/draco-2B3Fy6YM-py3.9/lib/python3.9/site-packages/nbclient/client.py", line 965, in async_execute_cell
    await self._check_raise_for_error(cell, cell_index, exec_reply)
  File "/home/runner/.virtualenvs/draco-2B3Fy6YM-py3.9/lib/python3.9/site-packages/nbclient/client.py", line 862, in _check_raise_for_error
    raise CellExecutionError.from_cell_and_msg(cell, exec_reply_content)
nbclient.exceptions.CellExecutionError: An error occurred while executing the following cell:
------------------
from draco import get_violations
from draco.asp_utils import blocks_to_program

c = "".join(
    blocks_to_program(
        constraints.blocks, set(constraints.blocks.keys()) - set(["violation"])
    )
)
prog = generate.program + define.program + helpers.program + hard.program + c + scatter

for model in run_clingo(prog + scatter, 1):
    pprint(answer_set_to_dict(model.answer_set))
    print(model.answer_set)
    answer = [str(symbol) + ". " for symbol in model.answer_set]
    print(get_violations(answer))
------------------

[0;31m---------------------------------------------------------------------------[0m
[0;31mImportError[0m                               Traceback (most recent call last)
Input [0;32mIn [2][0m, in [0;36m<cell line: 1>[0;34m()[0m
[0;32m----> 1[0m [38;5;28;01mfrom[39;00m [38;5;21;01mdraco[39;00m [38;5;28;01mimport[39;00m get_violations
[1;32m      2[0m [38;5;28;01mfrom[39;00m [38;5;21;01mdraco[39;00m[38;5;21;01m.[39;00m[38;5;21;01masp_utils[39;00m [38;5;28;01mimport[39;00m blocks_to_program
[1;32m      4[0m c [38;5;241m=[39m [38;5;124m"[39m[38;5;124m"[39m[38;5;241m.[39mjoin(
[1;32m      5[0m     blocks_to_program(
[1;32m      6[0m         constraints[38;5;241m.[39mblocks, [38;5;28mset[39m(constraints[38;5;241m.[39mblocks[38;5;241m.[39mkeys()) [38;5;241m-[39m [38;5;28mset[39m([[38;5;124m"[39m[38;5;124mviolation[39m[38;5;124m"[39m])
[1;32m      7[0m     )
[1;32m      8[0m )

[0;31mImportError[0m: cannot import name 'get_violations' from 'draco' (/home/runner/work/draco2/draco2/draco/__init__.py)
ImportError: cannot import name 'get_violations' from 'draco' (/home/runner/work/draco2/draco2/draco/__init__.py)

